#VRML_SIM R2022a utf8
WorldInfo {
  info [
    "Demo of a gantry robot playing the Hanoi Towers."
    "The robot moves a stack of colored blocks from one location to another, using the recursive Hanoi Towers algorithm."
    "Biologically Inspired Robotics Group (BIRG)."
  ]
  title "Gantry Robot"
  CFM 0.0001
  ERP 0.6
  basicTimeStep 4
  lineScale 0.5
}
Viewpoint {
  orientation -0.10476012594693003 -0.312975450331471 0.9439659334432555 5.0538515767335515
  position -0.7254927595803695 9.224549159125527 2.711275204745269
}
TexturedBackground {
}
TexturedBackgroundLight {
}
Floor {
  size 100 100
  appearance PBRAppearance {
    baseColorMap ImageTexture {
      url [
        "https://raw.githubusercontent.com/cyberbotics/webots/R2022a/projects/default/worlds/textures/grid.png"
      ]
    }
    roughness 1
    metalness 0
  }
}
DEF RAIL1 Solid {
  translation 0 -0.532 0.01
  children [
    DEF RAIL_SHAPE Shape {
      appearance DEF RAIL_APPEARANCE PBRAppearance {
        roughness 1
        metalness 0
      }
      geometry Box {
        size 80 0.02 0.02
      }
    }
  ]
  name "rail1"
  boundingObject USE RAIL_SHAPE
  locked TRUE
}
DEF RAIL2 Solid {
  translation 0 -0.468 0.01
  children [
    USE RAIL_SHAPE
  ]
  name "rail2"
  boundingObject USE RAIL_SHAPE
  locked TRUE
}
DEF RAIL3 Solid {
  translation 0 0.468 0.01
  children [
    USE RAIL_SHAPE
  ]
  name "rail3"
  boundingObject USE RAIL_SHAPE
  locked TRUE
}
DEF RAIL4 Solid {
  translation 0 0.532 0.01
  children [
    USE RAIL_SHAPE
  ]
  name "rail4"
  boundingObject USE RAIL_SHAPE
  locked TRUE
}
DEF GANTRY Robot {
  translation 0 0 0.98
  children [
    DEF PILLARS_GROUP Group {
      children [
        DEF BRIDGE_TRANS Transform {
          translation 0 0 0.11
          children [
            Shape {
              appearance DEF YELLOW_APPEARANCE PBRAppearance {
                baseColor 1 1 0
                roughness 1
                metalness 0
              }
              geometry Box {
                size 0.2 2.4 0.12
              }
            }
          ]
        }
        DEF PILLAR1_TRANS Transform {
          translation 0.4 -0.5 -0.44
          children [
            DEF PILLAR_SHAPE Shape {
              appearance USE YELLOW_APPEARANCE
              geometry Box {
                size 0.1 0.1 1
              }
            }
          ]
        }
        DEF PILLAR2_TRANS Transform {
          translation 0.4 0.5 -0.44
          children [
            USE PILLAR_SHAPE
          ]
        }
        DEF PILLAR3_TRANS Transform {
          translation -0.4 -0.5 -0.44
          children [
            USE PILLAR_SHAPE
          ]
        }
        DEF PILLAR4_TRANS Transform {
          translation -0.4 0.5 -0.44
          children [
            USE PILLAR_SHAPE
          ]
        }
        DEF TRANSVERSE1 Transform {
          translation 0 0.5 0.11
          children [
            DEF TRANSVERSE_SHAPE Shape {
              appearance USE YELLOW_APPEARANCE
              geometry Box {
                size 0.9 0.1 0.1
              }
            }
          ]
        }
        DEF TRANSVERSE2 Transform {
          translation 0 -0.5 0.11
          children [
            USE TRANSVERSE_SHAPE
          ]
        }
      ]
    }
    DEF WHEEL1_HINGE_JOINT HingeJoint {
      jointParameters HingeJointParameters {
        axis 0 -1 0
        anchor 0.4 -0.5 -0.9
      }
      device [
        RotationalMotor {
          name "wheel1_motor"
        }
      ]
      endPoint Solid {
        translation 0.4 -0.5 -0.9
        rotation 0 -1 0 0
        children [
          DEF WHEEL1_TRANS Transform {
            rotation -1 0 0 1.5708
            children [
              DEF WHEEL_SHAPE Shape {
                appearance DEF WHEEL_APPEARANCE PBRAppearance {
                  baseColor 0 0 0
                  roughness 1
                  metalness 0
                }
                geometry Cylinder {
                  height 0.04
                  radius 0.08
                }
              }
            ]
          }
        ]
        name "wheel1"
        boundingObject USE WHEEL1_TRANS
        physics DEF WHEEL_PHYSICS Physics {
        }
      }
    }
    DEF WHEEL2_HINGE_JOINT HingeJoint {
      jointParameters HingeJointParameters {
        axis 0 -1 0
        anchor 0.4 0.5 -0.9
      }
      device [
        RotationalMotor {
          name "wheel2_motor"
        }
      ]
      endPoint Solid {
        translation 0.4 0.5 -0.9
        rotation 0 -1 0 0
        children [
          DEF WHEEL2_TRANS Transform {
            rotation -1 0 0 1.5708
            children [
              USE WHEEL_SHAPE
            ]
          }
        ]
        name "wheel2"
        boundingObject USE WHEEL2_TRANS
        physics USE WHEEL_PHYSICS
      }
    }
    DEF WHEEL3_HINGE_JOINT HingeJoint {
      jointParameters HingeJointParameters {
        axis 0 -1 0
        anchor -0.4 -0.5 -0.9
      }
      device [
        RotationalMotor {
          name "wheel3_motor"
        }
      ]
      endPoint Solid {
        translation -0.4 -0.5 -0.9
        rotation 0 -1 0 0
        children [
          DEF WHEEL3_TRANS Transform {
            rotation -1 0 0 1.5708
            children [
              USE WHEEL_SHAPE
            ]
          }
        ]
        name "wheel3"
        boundingObject USE WHEEL3_TRANS
        physics USE WHEEL_PHYSICS
      }
    }
    DEF WHEEL4_HINGE_JOINT HingeJoint {
      jointParameters HingeJointParameters {
        axis 0 -1 0
        anchor -0.4 0.5 -0.9
      }
      device [
        RotationalMotor {
          name "wheel4_motor"
        }
      ]
      endPoint Solid {
        translation -0.4 0.5 -0.9
        rotation 0 -1 0 0
        children [
          DEF WHEEL4_TRANS Transform {
            rotation -1 0 0 1.5708
            children [
              USE WHEEL_SHAPE
            ]
          }
        ]
        name "wheel4"
        boundingObject USE WHEEL4_TRANS
        physics USE WHEEL_PHYSICS
      }
    }
    DEF BRIDGE_SLIDER_JOINT SliderJoint {
      jointParameters JointParameters {
        axis 0 -1 0
        minStop -1.16
        maxStop 1.16
      }
      device [
        LinearMotor {
          name "bridge_motor"
          maxVelocity 1
          minPosition -1.16
          maxPosition 1.16
          maxForce 100
        }
      ]
      endPoint Solid {
        rotation 0 0 1 1.5708
        children [
          GPS {
            name "bridge_motor_gps"
          }
          DEF TURRET_HINGE_JOINT HingeJoint {
            jointParameters HingeJointParameters {
              axis 0 0 1
              anchor 0 0 0.11
            }
            device [
              RotationalMotor {
                name "turret_motor"
                maxVelocity 3.14
                maxTorque 100
              }
            ]
            endPoint Solid {
              translation 0 0 0.11
              rotation 0 0 1 1.5708
              children [
                DEF TURRET_SHAPE Shape {
                  appearance USE WHEEL_APPEARANCE
                  geometry Cylinder {
                    height 0.16
                    radius 0.08
                  }
                }
                DEF LIFT_SLIDER_JOINT SliderJoint {
                  jointParameters JointParameters {
                    axis 0 0 -1
                  }
                  device [
                    LinearMotor {
                      name "lift_motor"
                      maxVelocity 1
                      maxPosition 0.73
                      maxForce 400
                    }
                  ]
                  endPoint Solid {
                    translation 0 0 0.36
                    rotation 0 -1 0 1.5708
                    children [
                      DEF PISTON_GROUP Group {
                        children [
                          Transform {
                            translation -0.5 0 0
                            children [
                              Shape {
                                appearance USE RAIL_APPEARANCE
                                geometry Box {
                                  size 0.04 0.2 0.4
                                }
                              }
                            ]
                          }
                          Transform {
                            rotation 0 -1 0 1.5708
                            children [
                              Shape {
                                appearance USE RAIL_APPEARANCE
                                geometry Cylinder {
                                  height 1
                                  radius 0.05
                                }
                              }
                            ]
                          }
                        ]
                      }
                      DEF GRIPPER_SLIDER_JOINT1 SliderJoint {
                        jointParameters JointParameters {
                        }
                        device [
                          LinearMotor {
                            name "grip_motor1"
                            maxPosition 0.18
                            maxForce 200
                          }
                        ]
                        endPoint Solid {
                          translation -0.6 0 -0.19
                          rotation 0 -1 0 -1.5708
                          children [
                            DEF GRIPPER_SHAPE Shape {
                              appearance USE RAIL_APPEARANCE
                              geometry Box {
                                size 0.02 0.2 0.16
                              }
                            }
                          ]
                          name "grip1"
                          boundingObject USE GRIPPER_SHAPE
                          physics Physics {
                          }
                        }
                      }
                      DEF GRIPPER_SLIDER_JOINT2 SliderJoint {
                        jointParameters JointParameters {
                          axis 0 0 -1
                        }
                        device [
                          LinearMotor {
                            name "grip_motor2"
                            maxPosition 0.18
                            maxForce 200
                          }
                        ]
                        endPoint Solid {
                          translation -0.6 0 0.19
                          rotation 0 -1 0 1.5708
                          children [
                            USE GRIPPER_SHAPE
                          ]
                          name "grip2"
                          boundingObject USE GRIPPER_SHAPE
                          physics Physics {
                          }
                        }
                      }
                    ]
                    boundingObject USE PISTON_GROUP
                    physics Physics {
                    }
                  }
                }
              ]
              boundingObject USE TURRET_SHAPE
              physics Physics {
              }
            }
          }
        ]
        boundingObject Box {
          size 0.1 0.1 0.1
        }
        physics Physics {
        }
      }
    }
  ]
  name "gantry"
  boundingObject USE PILLARS_GROUP
  physics Physics {
  }
  controller "<extern>"
}
DEF BOX_A1 Solid {
  translation 0 -0.8 0.15
  children [
    DEF BOX_SHAPE Shape {
      appearance PBRAppearance {
        baseColorMap ImageTexture {
          url [
            "https://raw.githubusercontent.com/devis12/ROS2-BDI/Webots_demo/simulations/webots_ros2_simulations/textures/A.png"
          ]
        }
        roughness 1
        metalness 0
      }
      geometry Box {
        size 0.2 0.2 0.2
      }
    }
  ]
  name "box A1"
  boundingObject USE BOX_SHAPE
  physics Physics {
  }
}
DEF BOX_A2 Solid {
  translation 0 -0.8 0.55
  children [
    DEF BOX_SHAPE Shape {
      appearance PBRAppearance {
        baseColorMap ImageTexture {
          url [
            "https://raw.githubusercontent.com/devis12/ROS2-BDI/Webots_demo/simulations/webots_ros2_simulations/textures/A.png"
          ]
        }
        roughness 1
        metalness 0
      }
      geometry Box {
        size 0.2 0.2 0.2
      }
    }
  ]
  name "box A2"
  boundingObject USE BOX_SHAPE
  physics Physics {
  }
}
DEF BOX_B1 Solid {
  translation -0.4 0 0.15
  children [
    DEF BOX_SHAPE Shape {
      appearance PBRAppearance {
        baseColorMap ImageTexture {
          url [
            "https://raw.githubusercontent.com/devis12/ROS2-BDI/Webots_demo/simulations/webots_ros2_simulations/textures/B.png"
          ]
        }
        roughness 1
        metalness 0
      }
      geometry Box {
        size 0.2 0.2 0.2
      }
    }
  ]
  name "box B1"
  boundingObject USE BOX_SHAPE
  physics Physics {
  }
}
DEF BOX_B2 Solid {
  translation -0.4 0 0.35
  children [
    DEF BOX_SHAPE Shape {
      appearance PBRAppearance {
        baseColorMap ImageTexture {
          url [
            "https://raw.githubusercontent.com/devis12/ROS2-BDI/Webots_demo/simulations/webots_ros2_simulations/textures/B.png"
          ]
        }
        roughness 1
        metalness 0
      }
      geometry Box {
        size 0.2 0.2 0.2
      }
    }
  ]
  name "box B2"
  boundingObject USE BOX_SHAPE
  physics Physics {
  }
}
DEF BOX_C1 Solid {
  translation -0.4 0 0.55
  children [
    DEF BOX_SHAPE Shape {
      appearance PBRAppearance {
        baseColorMap ImageTexture {
          url [
            "https://raw.githubusercontent.com/devis12/ROS2-BDI/Webots_demo/simulations/webots_ros2_simulations/textures/C.png"
          ]
        }
        roughness 1
        metalness 0
      }
      geometry Box {
        size 0.2 0.2 0.2
      }
    }
  ]
  name "box C1"
  boundingObject USE BOX_SHAPE
  physics Physics {
  }
}
DEF BOX_C2 Solid {
  translation 0 -0.8 0.35
  children [
    DEF BOX_SHAPE Shape {
      appearance PBRAppearance {
        baseColorMap ImageTexture {
          url [
            "https://raw.githubusercontent.com/devis12/ROS2-BDI/Webots_demo/simulations/webots_ros2_simulations/textures/C.png"
          ]
        }
        roughness 1
        metalness 0
      }
      geometry Box {
        size 0.2 0.2 0.2
      }
    }
  ]
  name "box C2"
  boundingObject USE BOX_SHAPE
  physics Physics {
  }
}
DEF PLATFORM_1 Solid {
  translation 0 -0.8 0.02
  rotation 0 0 1 -1.5707953071795862
  children [
    DEF PLATFORM1_SHAPE Shape {
      appearance PBRAppearance {
        baseColorMap ImageTexture {
          url [
            "https://raw.githubusercontent.com/devis12/ROS2-BDI/Webots_demo/simulations/webots_ros2_simulations/textures/1.png"
          ]
        }
        roughness 1
        metalness 0
      }
      geometry Box {
        size 0.4 0.4 0.04
      }
    }
  ]
  name "platform 1"
  boundingObject USE PLATFORM1_SHAPE
}
DEF PLATFORM_2 Solid {
  translation -0.4 0 0.02
  rotation 0 0 1 -1.5707953071795862
  children [
    DEF PLATFORM2_SHAPE Shape {
      appearance PBRAppearance {
        baseColorMap ImageTexture {
          url [
            "https://raw.githubusercontent.com/devis12/ROS2-BDI/Webots_demo/simulations/webots_ros2_simulations/textures/2.png"
          ]
        }
        roughness 1
        metalness 0
      }
      geometry Box {
        size 0.4 0.4 0.04
      }
    }
  ]
  name "platform 2"
  boundingObject USE PLATFORM2_SHAPE
}
DEF PLATFORM_A Solid {
  translation 2 0.8 -0.016
  rotation 0 0 1 -1.5707953071795862
  children [
    DEF PLATFORMA_SHAPE Shape {
      appearance PBRAppearance {
        baseColorMap ImageTexture {
          url [
            "https://raw.githubusercontent.com/devis12/ROS2-BDI/Webots_demo/simulations/webots_ros2_simulations/textures/A.png"
          ]
        }
        roughness 1
        metalness 0
      }
      geometry Box {
        size 0.4 0.4 0.04
      }
    }
  ]
  name "platform A"
  boundingObject USE PLATFORMA_SHAPE
}
DEF PLATFORM_B Solid {
  translation -0.5 0.8 -0.016
  rotation 0 0 1 -1.5707953071795862
  children [
    DEF PLATFORMB_SHAPE Shape {
      appearance PBRAppearance {
        baseColorMap ImageTexture {
          url [
            "https://raw.githubusercontent.com/devis12/ROS2-BDI/Webots_demo/simulations/webots_ros2_simulations/textures/B.png"
          ]
        }
        roughness 1
        metalness 0
      }
      geometry Box {
        size 0.4 0.4 0.04
      }
    }
  ]
  name "platform B"
  boundingObject USE PLATFORMB_SHAPE
}
DEF PLATFORM_C Solid {
  translation -3 0.8 -0.016
  rotation 0 0 1 -1.5707953071795862
  children [
    DEF PLATFORMC_SHAPE Shape {
      appearance PBRAppearance {
        baseColorMap ImageTexture {
          url [
            "https://raw.githubusercontent.com/devis12/ROS2-BDI/Webots_demo/simulations/webots_ros2_simulations/textures/C.png"
          ]
        }
        roughness 1
        metalness 0
      }
      geometry Box {
        size 0.4 0.4 0.04
      }
    }
  ]
  name "platform C"
  boundingObject USE PLATFORMC_SHAPE
}
DEF DEPOSIT_A Solid {
  translation 2 5.8 0
  rotation 0 0 1 -1.5707953071795862
  scale 5 5 5
  children [
    DEF DEPOSITA_SHAPE Shape {
      appearance PBRAppearance {
        baseColorMap ImageTexture {
          url [
            "https://raw.githubusercontent.com/devis12/ROS2-BDI/Webots_demo/simulations/webots_ros2_simulations/textures/A.png"
          ]
        }
        roughness 1
        metalness 0
      }
      geometry Box {
        size 0.4 0.4 0.04
      }
    }
  ]
  name "deposit A"
  boundingObject USE DEPOSITA_SHAPE
}
DEF DEPOSIT_B Solid {
  translation -0.5 5.8 0
  rotation 0 0 1 -1.5707953071795862
  scale 5 5 5
  children [
    DEF DEPOSITB_SHAPE Shape {
      appearance PBRAppearance {
        baseColorMap ImageTexture {
          url [
            "https://raw.githubusercontent.com/devis12/ROS2-BDI/Webots_demo/simulations/webots_ros2_simulations/textures/B.png"
          ]
        }
        roughness 1
        metalness 0
      }
      geometry Box {
        size 0.4 0.4 0.04
      }
    }
  ]
  name "deposit B"
  boundingObject USE DEPOSITB_SHAPE
}
DEF DEPOSIT_C Solid {
  translation -3 5.8 0
  rotation 0 0 1 -1.5707953071795862
  scale 5 5 5
  children [
    DEF DEPOSITC_SHAPE Shape {
      appearance PBRAppearance {
        baseColorMap ImageTexture {
          url [
            "https://raw.githubusercontent.com/devis12/ROS2-BDI/Webots_demo/simulations/webots_ros2_simulations/textures/C.png"
          ]
        }
        roughness 1
        metalness 0
      }
      geometry Box {
        size 0.4 0.4 0.04
      }
    }
  ]
  name "deposit C"
  boundingObject USE DEPOSITC_SHAPE
}
Robot {
  translation 2 4.48 0.1
  rotation 0 0 1 3.1416
  children [
    InertialUnit {
    }
    GPS {
    }
    DEF BODY Shape {
      appearance PBRAppearance {
        baseColor 0.533333 0.541176 0.521569
        roughness 1
        metalness 0
      }
      geometry Box {
        size 0.9 0.44 0.08
      }
    }
    DEF WHEEL1 HingeJoint {
      jointParameters HingeJointParameters {
        position 1886.4311572226009
        axis 0 1 0
        anchor 0.26 0.24 0
      }
      device [
        RotationalMotor {
          name "ca_wheel1"
          maxVelocity 36
        }
      ]
      endPoint Solid {
        translation 0.26 0.24 0
        rotation 0.6139858291679015 0.5581304117747092 -0.5581324619059513 2.0403163717567523
        children [
          DEF WHEEL Shape {
            appearance PBRAppearance {
              baseColor 0 0 0
              roughness 1
              metalness 0
            }
            geometry Cylinder {
              height 0.04
              radius 0.1
              subdivision 24
            }
          }
        ]
        boundingObject USE WHEEL
        physics Physics {
        }
      }
    }
    DEF WHEEL2 HingeJoint {
      jointParameters HingeJointParameters {
        position 849.6327809150216
        axis 0 1 0
        anchor 0.26 -0.24 0
      }
      device [
        RotationalMotor {
          name "ca_wheel2"
          maxVelocity 36
        }
      ]
      endPoint Solid {
        translation 0.26 -0.24 0
        rotation -0.6419131266283836 -0.5421924834458128 0.5421944750336677 4.282927763579224
        children [
          USE WHEEL
        ]
        name "solid(1)"
        boundingObject USE WHEEL
        physics Physics {
        }
      }
    }
    DEF WHEEL3 HingeJoint {
      jointParameters HingeJointParameters {
        position 1886.4312190274604
        axis 0 1 0
        anchor -0.26 0.24 0
      }
      device [
        RotationalMotor {
          name "ca_wheel3"
          maxVelocity 36
        }
      ]
      endPoint Solid {
        translation -0.26 0.24 0
        rotation 0.6139620795454026 0.5581434745151869 -0.5581455246944113 2.0403508673321484
        children [
          USE WHEEL
        ]
        name "solid(2)"
        boundingObject USE WHEEL
        physics Physics {
        }
      }
    }
    DEF WHEEL4 HingeJoint {
      jointParameters HingeJointParameters {
        position 849.6328424186684
        axis 0 1 0
        anchor -0.26 -0.24 0
      }
      device [
        RotationalMotor {
          name "ca_wheel4"
          maxVelocity 36
        }
      ]
      endPoint Solid {
        translation -0.26 -0.24 0
        rotation -0.6418895828156815 -0.5422064199683497 0.5422084116073964 4.282894416335675
        children [
          USE WHEEL
        ]
        name "solid(3)"
        boundingObject USE WHEEL
        physics Physics {
        }
      }
    }
  ]
  name "carrier_a"
  boundingObject USE BODY
  physics Physics {
    density -1
    mass 1
  }
  controller "<extern>"
}
Robot {
  translation -0.5 8.32 0.1
  rotation 0 0 1 1.5708
  children [
    GPS {
    }
    DEF BODY Shape {
      appearance PBRAppearance {
        baseColor 0.533333 0.541176 0.521569
        roughness 1
        metalness 0
      }
      geometry Box {
        size 0.9 0.44 0.08
      }
    }
    DEF WHEEL1 HingeJoint {
      jointParameters HingeJointParameters {
        position 1886.4311572226009
        axis 0 1 0
        anchor 0.26 0.24 0
      }
      device [
        RotationalMotor {
          name "ca_wheel1"
        }
      ]
      endPoint Solid {
        translation 0.26 0.24 0
        rotation 0.6139858291679015 0.5581304117747092 -0.5581324619059513 2.0403163717567523
        children [
          DEF WHEEL Shape {
            appearance PBRAppearance {
              baseColor 0 0 0
              roughness 1
              metalness 0
            }
            geometry Cylinder {
              height 0.04
              radius 0.1
              subdivision 24
            }
          }
        ]
        boundingObject USE WHEEL
        physics Physics {
        }
      }
    }
    DEF WHEEL2 HingeJoint {
      jointParameters HingeJointParameters {
        position 849.6327809150216
        axis 0 1 0
        anchor 0.26 -0.24 0
      }
      device [
        RotationalMotor {
          name "ca_wheel2"
        }
      ]
      endPoint Solid {
        translation 0.26 -0.24 0
        rotation -0.6419131266283836 -0.5421924834458128 0.5421944750336677 4.282927763579224
        children [
          USE WHEEL
        ]
        name "solid(1)"
        boundingObject USE WHEEL
        physics Physics {
        }
      }
    }
    DEF WHEEL3 HingeJoint {
      jointParameters HingeJointParameters {
        position 1886.4312190274604
        axis 0 1 0
        anchor -0.26 0.24 0
      }
      device [
        RotationalMotor {
          name "ca_wheel3"
        }
      ]
      endPoint Solid {
        translation -0.26 0.24 0
        rotation 0.6139620795454026 0.5581434745151869 -0.5581455246944113 2.0403508673321484
        children [
          USE WHEEL
        ]
        name "solid(2)"
        boundingObject USE WHEEL
        physics Physics {
        }
      }
    }
    DEF WHEEL4 HingeJoint {
      jointParameters HingeJointParameters {
        position 849.6328424186684
        axis 0 1 0
        anchor -0.26 -0.24 0
      }
      device [
        RotationalMotor {
          name "ca_wheel4"
        }
      ]
      endPoint Solid {
        translation -0.26 -0.24 0
        rotation -0.6418895828156815 -0.5422064199683497 0.5422084116073964 4.282894416335675
        children [
          USE WHEEL
        ]
        name "solid(3)"
        boundingObject USE WHEEL
        physics Physics {
        }
      }
    }
  ]
  name "carrier_b"
  boundingObject USE BODY
  physics Physics {
    density -1
    mass 1
  }
}
Robot {
  translation -3 8.32 0.1
  rotation 0 0 1 1.5708
  children [
    GPS {
    }
    DEF BODY Shape {
      appearance PBRAppearance {
        baseColor 0.533333 0.541176 0.521569
        roughness 1
        metalness 0
      }
      geometry Box {
        size 0.9 0.44 0.08
      }
    }
    DEF WHEEL1 HingeJoint {
      jointParameters HingeJointParameters {
        position 1886.4311572226009
        axis 0 1 0
        anchor 0.26 0.24 0
      }
      device [
        RotationalMotor {
          name "ca_wheel1"
        }
      ]
      endPoint Solid {
        translation 0.26 0.24 0
        rotation 0.6139858291679015 0.5581304117747092 -0.5581324619059513 2.0403163717567523
        children [
          DEF WHEEL Shape {
            appearance PBRAppearance {
              baseColor 0 0 0
              roughness 1
              metalness 0
            }
            geometry Cylinder {
              height 0.04
              radius 0.1
              subdivision 24
            }
          }
        ]
        boundingObject USE WHEEL
        physics Physics {
        }
      }
    }
    DEF WHEEL2 HingeJoint {
      jointParameters HingeJointParameters {
        position 849.6327809150216
        axis 0 1 0
        anchor 0.26 -0.24 0
      }
      device [
        RotationalMotor {
          name "ca_wheel2"
        }
      ]
      endPoint Solid {
        translation 0.26 -0.24 0
        rotation -0.6419131266283836 -0.5421924834458128 0.5421944750336677 4.282927763579224
        children [
          USE WHEEL
        ]
        name "solid(1)"
        boundingObject USE WHEEL
        physics Physics {
        }
      }
    }
    DEF WHEEL3 HingeJoint {
      jointParameters HingeJointParameters {
        position 1886.4312190274604
        axis 0 1 0
        anchor -0.26 0.24 0
      }
      device [
        RotationalMotor {
          name "ca_wheel3"
        }
      ]
      endPoint Solid {
        translation -0.26 0.24 0
        rotation 0.6139620795454026 0.5581434745151869 -0.5581455246944113 2.0403508673321484
        children [
          USE WHEEL
        ]
        name "solid(2)"
        boundingObject USE WHEEL
        physics Physics {
        }
      }
    }
    DEF WHEEL4 HingeJoint {
      jointParameters HingeJointParameters {
        position 849.6328424186684
        axis 0 1 0
        anchor -0.26 -0.24 0
      }
      device [
        RotationalMotor {
          name "ca_wheel4"
        }
      ]
      endPoint Solid {
        translation -0.26 -0.24 0
        rotation -0.6418895828156815 -0.5422064199683497 0.5422084116073964 4.282894416335675
        children [
          USE WHEEL
        ]
        name "solid(3)"
        boundingObject USE WHEEL
        physics Physics {
        }
      }
    }
  ]
  name "carrier_c"
  boundingObject USE BODY
  physics Physics {
    density -1
    mass 1
  }
}
